{
  "timestamp": "2025-07-02_09-56-43",
  "active_window": "ChatGPT",
  "focused_text": "Could not extract AXValue from focused element",
  "clipboard": "curl -X POST http://127.0.0.1:8000/generate \\\n     -H \"Content-Type: application/json\" \\\n     -d '{\"scenario\":\"missed class\",\"urgency\":\"panic\"}'",
  "vscode_text": "OPENAI_API_KEY=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",
  "ocr_text": "ChatGPT File Edit View Window\u2019 Help\n\n= List of research pape X * Artificial Intelligence X CO NLP_1.ipynb - Colab X CO NLP_1.ipynb - Colab X ca LAUNCHED Global X\n\nof\n\n\u20ac7> C#@ \u00a9 8\n\nplatform.openai.com/settings/organization/api-keys\n\n@ O\n\nM Launched - Artificie\n\n\u00a9 &8 \u00a9BO S 32%) FF Q S @ Wed Jul2 9:56AM\nx Artificial_Intelligence_Ce X (B\u00ae al-05-BBLEN4 x \u00a9 Opendl x So API keys - OpenAl A! X\n\nIntelligent Excuse Generator Plan >\nBhuvan\n\neco MO @G\n\nC \u20ac- 5 P excuse-generator By obOWd\neq oO EXPLORER J Welcome \u00ae excuse_api.py 4, U \u00a9 .env Ux >\n|\nV EXCUSE-GENERATOR  .env\n\u00a9 SEN > \u2014pycache_ 1 OPENAT_API_KEY=sk-proj-\u2014fbjMM3ZWBJFWqcoNxxImtmkgmE L5ner8TF5Hw8isFAx8uZ\\\nv venv\npay > lia PROBLEMS @ OUTPUT DEBUGCONSOLE TERMINAL PORTS. dv om A SM\n> include OO\n\u2018 . raise exc * | BJ python3.11\n- S > lib File \"/Users/bhuvanarora/excuse-generator/.venv/lib/python3.11/site-packages/starlette/_exception_handler.py\", lin h\n& \u00a9 pyvenv.cfg U e 42, in wrapped_app =) Zs!\n\u00a9 env 7; await app(scope, receive, sender)\n3 File \"/Users/bhuvanarora/excuse-generator/.venv/1lib/python3.11/site-packages/starlette/routing.py\", line 73, in a\nES e excuse_apipy 4u. 9 ny paces S-Py Pa Thought for 20 seconds >\n. ~ \u2018 response = await f(request)\n{} history.json u RRR RRNA The traceback tells us exactly what's wrong\nA = requirements.txt U File \"/Users/bhuvanarora/excuse-generator/.venv/lib/python3.11/site-packages/fastapi/routing.py\", line 301, in app\nraw_response = await run_endpoint_function(\nFile \"/Users/bhuvanarora/excuse-generator/.venv/lib/python3.11/site-packages/fastapi/routing.py\", line 214, in run (a) Copy\n_endpoint_function\nreturn await run_in_threadpool(dependant.call, *values)\n; A000 AAAA ALLARD A PAAAARAS ELD P AAAS SLLAPAAARS REAL AAAN ; ; ; openai.AuthenticationError: .. {\"message\":\"Incorrect API key provided: you\nFile \"/Users/bhuvanarora/excuse-generator/.venv/lib/python3.11/site-packages/starlette/concurrency.py\", line 37, i\nn run_in_threadpool\nreturn await anyio.to_thread. run_sync( func) . . wae . . .\nA000 ALDIAALALDAAAAADAAAAAAADAAAAAD AA That means FastAPI is still picking up the placeholder string your_api_key instead of the\nFile \"/Users/bhuvanarora/excuse-generator/.venv/lib/python3.11/site-packages/anyio/to_thread.py\", line 56, in run_\nsync i\nreturn await get_async_backend().run_sync_in_worker_thread( . secret you just pasted.\nAAA AAAAARAAAAAAAAAAAAAAAAAAAAAAAAARARAAAAAAARARAAAAA 1 . 0 :\nFile \"/Users/bhuvanarora/excuse-generator/.venv/lib/python3.11/site-packages/anyio/_backends/_asyncio.py\", line 24 Let's wipe the placeholder and be 100 % sure the real key is loaded.\n70, in run_sync_in_worker_thread\nreturn await future\nFile \"/Users/bhuvanarora/excuse-generator/.venv/lib/python3.11/site-packages/anyio/_backends/_asyncio.py\", line 96\n7, in run\na eee 1 \u2014 Remove / override the bad value\nF File \"/Users/bhuvanarora/excuse-generator/excuse_api.py\", line 37, in generate\nres = client.chat.completions.create(\nFile \"/Users/bhuvanarora/excuse-generator/.venv/lib/python3.11/site-packages/openai/_utils/_utils.py\", line 287, i A. Make sure no shell variable is set\nn wrapper\nreturn func(*args, +kkwargs)\nFile \"/Users/bhuvanarora/excuse-generator/.venv/lib/python3.11/site-packages/openai/resources/chat/completions/com bash oO Copy\npletions.py\", line 1087, in create\nreturn self._post(\nFile \"/Users/bhuvanarora/excuse-generator/.venv/lib/python3.11/site-packages/openai/_base_client.py\", line 1249, i echo $OPENAI_API_KEY\nn post\nreturn cast(ResponseT, self.request(cast_to, opts, stream=stream, stream_cls=stream_cls) ) |\nFile \"/Users/bhuvanarora/excuse-generator/.venv/lib/python3.11/site-packages/openai/_base_client.py\", line 1037, i If it prints your_api_key (or anything at all):\nn request v\n(2) raise self._make_status_error_from_response(err.response) from None\nopenai.AuthenticationError: Error code: 401 - {'error': {'message': \u2018Incorrect API key provided: your_api_key. You c k }\nsb > OUTLINE an find your API key at https://platform.openai.com/account/api-keys.', \u2018type': \u2018invalid_request_error', \u2018param': No\n, \u2018code': \u2018i Lid i_key' a\n> TIMELINE nr cone Are Lana ( Work with Code Tab x\n| maint @ @Wo0A4 Q _Ln1,Col180 Spaces:4 UTF-8 LF {} Properties 8 (|\n\n880068820\n\nMessage Bhuvan\n\n+ @\u00ae\n\n{ | f \u00a2\nSe : \u00a9)\n/ =\n. . . .\n\nen\n\nWw"
}