{
  "timestamp": "2025-07-02_09-57-08",
  "active_window": "Electron",
  "focused_text": "Could not extract AXValue from focused element",
  "clipboard": "echo $OPENAI_API_KEY           # \u2190 should print nothing",
  "vscode_text": "OPENAI_API_KEY=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",
  "ocr_text": "6\n\no\nS\n\n\u00a9\n\nCode File Edit Selection View Go Run Terminal Window\u2019 Help\n\n=} List of research pape X Artificial Intelligence X CO NLP_1.ipynb - Colab X CO NLP_1.ipynb - Colab X [a LAUNCHED Global X @ Launched - Artificiz\n\u20ac 7 CQ O @G = platform.openai.com/settings/organization/api-keys\ne@e@ < \u00a3 excuse-generator By oO WW\n| oO EXPLORER + J Welcome \u00ae excuse_api.py 4, U env UX >\nV EXCUSE-GENERATOR  .env\n> \u2014Pycache_ 1 OPENAT_API_KEY=sk-proj-\u2014fbjMM3ZWBJFWqcoNxxImtmkgmE L5ner8TF5Hw8isFAx8uZ\\\nv venv\n> le PROBLEMS @ OUTPUT DEBUGCONSOLE TERMINAL PORTS. tv A X\n> include OO\n. raise exc * | BJ python3.11\n> lib File \"/Users/bhuvanarora/excuse-generator/.venv/lib/python3.11/site-packages/starlette/_exception_handler.py\", lin x] zsh\n\ne 42, in wrapped_app\nawait app(scope, receive, sender)\nFile \"/Users/bhuvanarora/excuse-generator/.venv/lib/python3.11/site-packages/starlette/routing.py\", line 73, in ap ,\nt\n\n\u00a9 pyvenv.cfg\n& .env\n\n@ excuse_api.py 4,\n\nresponse = await f(request)\nFile \"/Users/bhuvanarora/excuse-generator/.venv/lib/python3.11/site-packages/fastapi/routing.py\", line 301, in app\nraw_response = await run_endpoint_function(\n\nU\n\nU\n\nU p\n{} history.json U\nU\n\n=> BY & oO\n\n= requirements.txt\n\nFile \"/Users/bhuvanarora/excuse-generator/.venv/lib/python3.11/site-packages/fastapi/routing.py\", line 214, in run\n_endpoint_function\nreturn await run_in_threadpool(dependant.call, *values)\nFile \"/Users/bhuvanarora/excuse-generator/.venv/lib/python3.11/site-packages/starlette/concurrency.py\", line 37, i\nn run_in_threadpool\nreturn await anyio.to_thread. run_sync( func)\nFile \"/Users/bhuvanarora/excuse-generator/.venv/lib/python3.11/site-packages/anyio/to_thread.py\", line 56, in run_\nsync\nreturn await get_async_backend().run_sync_in_worker_thread( .\nFile \"/Users/bhuvanarora/excuse-generator/.venv/lib/python3.11/site-packages/anyio/_backends/_asyncio.py\", line 24\n70, in run_sync_in_worker_thread\nreturn await future\nFile \"/Users/bhuvanarora/excuse-generator/.venv/lib/python3.11/site-packages/anyio/_backends/_asyncio.py\", line 96\n7, in run\nresult = context.run(func, xargs)\nFile \"/Users/bhuvanarora/excuse-generator/excuse_api.py\", line 37, in generate\nres = client.chat.completions.create(\nFile \"/Users/bhuvanarora/excuse-generator/.venv/lib/python3.11/site-packages/openai/_utils/_utils.py\", line 287, i\nn wrapper\nreturn func(*args, +kkwargs)\nFile \"/Users/bhuvanarora/excuse-generator/.venv/lib/python3.11/site-packages/openai/resources/chat/completions/com\npletions.py\", line 1087, in create\nreturn self._post(\nFile \"/Users/bhuvanarora/excuse-generator/.venv/lib/python3.11/site-packages/openai/_base_client.py\", line 1249, i\nn post\nreturn cast(ResponseT, self.request(cast_to, opts, stream=stream, stream_cls=stream_cls) )\n\nFile \"/Users/bhuvanarora/excuse-generator/.venv/lib/python3.11/site-packages/openai/_base_client.py\", line 1037, i\n\n(2) n request\nraise self._make_status_error_from_response(err.response) from None\nopenai.AuthenticationError: Error code: 401 - {'error': {'message': \u2018Incorrect API key provided: your_api_key. You c\n> OUTLINE an find your API key at https://platform.openai.com/account/api-keys.', \u2018type': \u2018invalid_request_error', \u2018param': No\n$03 ne, \u2018code': 'invalid_api_key'}}\n> TIMELINE echo $OPENAT_API_KEY # \u00a9 should print nothing\nLi | maint @ @Wo0A4 Q_Ln1,Col180 Spaces:4 UTF-8 LF {} Properties @& QO\n\n880068820\n\nx\n\n\u00a9 & \u00a9BO S 32% FF Q S 6 Wed Jul2 9:57AM\n\nArtificial_Intelligence_Ce X J Al-05-BBLEN4 xX \u00a9 Openal\n\nMaccy\n@ echo $OPENAI_API_KEY # \u20ac should\n\nIntelligent Excuse Generator Plan > print nothing\n\nBhuvan\n\nIne traceback tells us exactly wnat\u2019s wrong \"\n\u00a9) Copy\n\nopenai.AuthenticationError: .. {\"message\":\"Incorrect API key provided: you\n\nThat means FastAPI is still picking up the placeholder string your_api_key instead of the\nsecret you just pasted.\nLet's wipe the placeholder and be 100 % sure the real key is loaded.\n\n1 \u2014 Remove / override the bad value\n\nA. Make sure no shell variable is set\nbash Y Copied\necho $O0PENAI_API_KEY\n\nIf it prints your_api_key (or anything at all):\nbash O) Copy\nunset OPENAI_API_KEY\n\nB. Ensure only the real key exists in files\n\n* .env > has the one true key (already done).\n\n+ .env.sample - delete or rename it so python-dotenv can\u2019t load the placeholder: |\n\nbash O) Copy\n\nMessage Bhuvan\n\n+ @\u00ae@ ov\n\n\u00a9\n\n\u00ae\n\n{ } fi \u00a2\n\n\u00a9 & : 2)\n\n\u2014 =\n. . . ."
}