{
  "timestamp": "2025-07-02_10-52-46",
  "active_window": "ChatGPT",
  "focused_text": "Could not extract AXValue from focused element",
  "clipboard": "(.venv) bhuvanarora@Bhuvans-MacBook-Pro excuse-generator % uvicorn excuse_api:app --reload       \nINFO:     Will watch for changes in these directories: ['/Users/bhuvanarora/excuse-generator']\nINFO:     Uvicorn running on http://127.0.0.1:8000 (Press CTRL+C to quit)\nINFO:     Started reloader process [4496] using StatReload\nINFO:     Started server process [4498]\nINFO:     Waiting for application startup.\nINFO:     Application startup complete.\nINFO:     127.0.0.1:65265 - \"POST /generate HTTP/1.1\" 500 Internal Server Error\nERROR:    Exception in ASGI application\nTraceback (most recent call last):\n  File \"/Users/bhuvanarora/excuse-generator/.venv/lib/python3.11/site-packages/uvicorn/protocols/http/h11_impl.py\", line 403, in run_asgi\n    result = await app(  # type: ignore[func-returns-value]\n             ^^^^^^^^^^^^^^^^^^^^^^^^^^^^^^^^^^^^^^^^^^^^^^\n  File \"/Users/bhuvanarora/excuse-generator/.venv/lib/python3.11/site-packages/uvicorn/middleware/proxy_headers.py\", line 60, in __call__\n    return await self.app(scope, receive, send)\n           ^^^^^^^^^^^^^^^^^^^^^^^^^^^^^^^^^^^^\n  File \"/Users/bhuvanarora/excuse-generator/.venv/lib/python3.11/site-packages/fastapi/applications.py\", line 1054, in __call__\n    await super().__call__(scope, receive, send)\n  File \"/Users/bhuvanarora/excuse-generator/.venv/lib/python3.11/site-packages/starlette/applications.py\", line 112, in __call__\n    await self.middleware_stack(scope, receive, send)\n  File \"/Users/bhuvanarora/excuse-generator/.venv/lib/python3.11/site-packages/starlette/middleware/errors.py\", line 187, in __call__\n    raise exc\n  File \"/Users/bhuvanarora/excuse-generator/.venv/lib/python3.11/site-packages/starlette/middleware/errors.py\", line 165, in __call__\n    await self.app(scope, receive, _send)\n  File \"/Users/bhuvanarora/excuse-generator/.venv/lib/python3.11/site-packages/starlette/middleware/exceptions.py\", line 62, in __call__\n    await wrap_app_handling_exceptions(self.app, conn)(scope, receive, send)\n  File \"/Users/bhuvanarora/excuse-generator/.venv/lib/python3.11/site-packages/starlette/_exception_handler.py\", line 53, in wrapped_app\n    raise exc\n  File \"/Users/bhuvanarora/excuse-generator/.venv/lib/python3.11/site-packages/starlette/_exception_handler.py\", line 42, in wrapped_app\n    await app(scope, receive, sender)\n  File \"/Users/bhuvanarora/excuse-generator/.venv/lib/python3.11/site-packages/starlette/routing.py\", line 714, in __call__\n    await self.middleware_stack(scope, receive, send)\n  File \"/Users/bhuvanarora/excuse-generator/.venv/lib/python3.11/site-packages/starlette/routing.py\", line 734, in app\n    await route.handle(scope, receive, send)\n  File \"/Users/bhuvanarora/excuse-generator/.venv/lib/python3.11/site-packages/starlette/routing.py\", line 288, in handle\n    await self.app(scope, receive, send)\n  File \"/Users/bhuvanarora/excuse-generator/.venv/lib/python3.11/site-packages/starlette/routing.py\", line 76, in app\n    await wrap_app_handling_exceptions(app, request)(scope, receive, send)\n  File \"/Users/bhuvanarora/excuse-generator/.venv/lib/python3.11/site-packages/starlette/_exception_handler.py\", line 53, in wrapped_app\n    raise exc\n  File \"/Users/bhuvanarora/excuse-generator/.venv/lib/python3.11/site-packages/starlette/_exception_handler.py\", line 42, in wrapped_app\n    await app(scope, receive, sender)\n  File \"/Users/bhuvanarora/excuse-generator/.venv/lib/python3.11/site-packages/starlette/routing.py\", line 73, in app\n    response = await f(request)\n               ^^^^^^^^^^^^^^^^\n  File \"/Users/bhuvanarora/excuse-generator/.venv/lib/python3.11/site-packages/fastapi/routing.py\", line 301, in app\n    raw_response = await run_endpoint_function(\n                   ^^^^^^^^^^^^^^^^^^^^^^^^^^^^\n  File \"/Users/bhuvanarora/excuse-generator/.venv/lib/python3.11/site-packages/fastapi/routing.py\", line 214, in run_endpoint_function\n    return await run_in_threadpool(dependant.call, **values)\n           ^^^^^^^^^^^^^^^^^^^^^^^^^^^^^^^^^^^^^^^^^^^^^^^^^\n  File \"/Users/bhuvanarora/excuse-generator/.venv/lib/python3.11/site-packages/starlette/concurrency.py\", line 37, in run_in_threadpool\n    return await anyio.to_thread.run_sync(func)\n           ^^^^^^^^^^^^^^^^^^^^^^^^^^^^^^^^^^^^\n  File \"/Users/bhuvanarora/excuse-generator/.venv/lib/python3.11/site-packages/anyio/to_thread.py\", line 56, in run_sync\n    return await get_async_backend().run_sync_in_worker_thread(\n           ^^^^^^^^^^^^^^^^^^^^^^^^^^^^^^^^^^^^^^^^^^^^^^^^^^^^\n  File \"/Users/bhuvanarora/excuse-generator/.venv/lib/python3.11/site-packages/anyio/_backends/_asyncio.py\", line 2470, in run_sync_in_worker_thread\n    return await future\n           ^^^^^^^^^^^^\n  File \"/Users/bhuvanarora/excuse-generator/.venv/lib/python3.11/site-packages/anyio/_backends/_asyncio.py\", line 967, in run\n    result = context.run(func, *args)\n             ^^^^^^^^^^^^^^^^^^^^^^^^\n  File \"/Users/bhuvanarora/excuse-generator/excuse_api.py\", line 43, in generate\n    out = json.loads(model.generate_content(full_prompt).text)\n                     ^^^^^^^^^^^^^^^^^^^^^^^^^^^^^^^^^^^\n  File \"/Users/bhuvanarora/excuse-generator/.venv/lib/python3.11/site-packages/google/generativeai/generative_models.py\", line 331, in generate_content\n    response = self._client.generate_content(\n               ^^^^^^^^^^^^^^^^^^^^^^^^^^^^^^\n  File \"/Users/bhuvanarora/excuse-generator/.venv/lib/python3.11/site-packages/google/ai/generativelanguage_v1beta/services/generative_service/client.py\", line 835, in generate_content\n    response = rpc(\n               ^^^^\n  File \"/Users/bhuvanarora/excuse-generator/.venv/lib/python3.11/site-packages/google/api_core/gapic_v1/method.py\", line 131, in __call__\n    return wrapped_func(*args, **kwargs)\n           ^^^^^^^^^^^^^^^^^^^^^^^^^^^^^\n  File \"/Users/bhuvanarora/excuse-generator/.venv/lib/python3.11/site-packages/google/api_core/retry/retry_unary.py\", line 294, in retry_wrapped_func\n    return retry_target(\n           ^^^^^^^^^^^^^\n  File \"/Users/bhuvanarora/excuse-generator/.venv/lib/python3.11/site-packages/google/api_core/retry/retry_unary.py\", line 156, in retry_target\n    next_sleep = _retry_error_helper(\n                 ^^^^^^^^^^^^^^^^^^^^\n  File \"/Users/bhuvanarora/excuse-generator/.venv/lib/python3.11/site-packages/google/api_core/retry/retry_base.py\", line 214, in _retry_error_helper\n    raise final_exc from source_exc\n  File \"/Users/bhuvanarora/excuse-generator/.venv/lib/python3.11/site-packages/google/api_core/retry/retry_unary.py\", line 147, in retry_target\n    result = target()\n             ^^^^^^^^\n  File \"/Users/bhuvanarora/excuse-generator/.venv/lib/python3.11/site-packages/google/api_core/timeout.py\", line 130, in func_with_timeout\n    return func(*args, **kwargs)\n           ^^^^^^^^^^^^^^^^^^^^^\n  File \"/Users/bhuvanarora/excuse-generator/.venv/lib/python3.11/site-packages/google/api_core/grpc_helpers.py\", line 78, in error_remapped_callable\n    raise exceptions.from_grpc_error(exc) from exc\ngoogle.api_core.exceptions.NotFound: 404 models/gemini-pro is not found for API version v1beta, or is not supported for generateContent. Call ListModels to see the list of available models and their supported methods.\n",
  "vscode_text": "# excuse_api.py\nimport os, json, time, hashlib\nfrom pathlib import Path\nfrom dotenv import load_dotenv, find_dotenv\nload_dotenv(find_dotenv(), override=True)\n\n\n\nfrom fastapi import FastAPI\nfrom pydantic import BaseModel\n\nimport google.generativeai as genai\ngenai.configure(api_key=os.getenv(\"GEMINI_KEY\"))\nmodel = genai.GenerativeModel(\"models/gemini-pro\")\n#print(\">>> model being used:\", model._name) \n# ---------- simple \u201cDB\u201d ----------\nDATA = Path(\"history.json\")\nif not DATA.exists():\n    DATA.write_text(\"[]\")          # seed empty list\n\n\n\n# ---------- FastAPI app ----------\napp = FastAPI()\n\nclass Req(BaseModel):\n    scenario: str  # e.g. \"missed class\"\n    urgency: str   # \"low\" | \"medium\" | \"panic\"\n\nSYSTEM_PROMPT = \"\"\"\nYou are an elite alibi-creator.\nReturn a JSON with:\n  excuse               (\u2264 50 words),\n  believability_score  (0-1),\n  chat_log             (short WhatsApp-style proof)\n\"\"\"\n\n# ---------- /generate ----------\n@app.post(\"/generate\")\ndef generate(r: Req):\n    prompt = f\"Scenario: {r.scenario}\\nUrgency: {r.urgency}\"\n    full_prompt = f\"{SYSTEM_PROMPT}\\nScenario: {r.scenario}\\nUrgency: {r.urgency}\"\n    out = json.loads(model.generate_content([full_prompt]).text)\n    entry = {\n        \"id\": hashlib.md5(out[\"excuse\"].encode()).hexdigest(),\n        \"ts\": time.time(),\n        **out,\n    }\n\n    history = json.loads(DATA.read_text())\n    if entry[\"id\"] not in {h[\"id\"] for h in history}:   # de-dupe\n        history.append(entry)\n        DATA.write_text(json.dumps(history, indent=2))\n\n    return entry\n\n# ---------- /top?n=5 ----------\n@app.get(\"/top\")\ndef top(n: int = 5):\n    history = json.loads(DATA.read_text())\n    history.sort(key=lambda x: x[\"believability_score\"], reverse=True)\n    return history[:n]",
  "ocr_text": "Ow \u00ae OF\n\nChatGPT File Edit View Window\u2019 Help\n\u00a9 List of research =) Artificial Intellige CO NLP_1.ipynb - Cc CO NLP_1.ipynb - Cc BB Launcre Glot \u2122 Launched - Artif Artificial_Intelligenc\n<> C #8 O & \u00a9 aistudio.google.com/apikey\n\nGoogle Al Studio\n\nEXPLORER\noa\n\n\\Y EXCUSE-GENERATOR\n\nil Us\n\nP > __pycache__\n\nVV venv\n\n& > bin\n\u2014| Ch > include\n\nView stat\n\n> lib\n>\n& \u00a9 pyvenv.cfg\n\n\u00a9 .env\n\nHS @ excuse_api.py\n\n{} history.json\nA = requirements.txt\n\n@\n$03 > OUTLINE\n\n> TIMELINE\n\n(GE & mains @0A4\nus\n\n4\n\nU\nU\nU\nU\nU\n\n\u20ac P excuse-generator By os Oo\n\nx Welcome @ excuse_api.py 4,U @\u00ae % .env U Dy\n\u00ae excuse_api.py > \u00a9 top\n\n4Q\u00ae def generate(r: Req):\n\n41 prompt = f\"Scenario: {r.scenario}\\nUrgency: {r.urgency}\"\n42 full_prompt = f\"{SYSTEM_PROMPT}\\nScenario: {r.scenario}\\nUrgency:\n43 out = json. loads(model.generate_content( [full_prompt] ).text)\n44 entry = {\n45 \"id\": hashlib.md5(out[\"excuse\"].encode()).hexdigest(),\n\nPROBLEMS @ OUTPUT DEBUG CONSOLE TERMINAL PORTS + v\n\n7, in run \u201c| 23) pyth\u00a2\nresult = context.run(func, xargs) 2) zsh\n\nFile \"/Users/bhuvanarora/excuse-generator/excuse_api.py\", line 43, in generate\nout = json. loads(model.generate_content(full_prompt) .text)\nAAAAAAAAAAAAAAAAAAAAAAAAAAARAAAAARA I,\nFile \"/Users/bhuvanarora/excuse-generator/.venv/lib/python3.11/site-packages/google/generativeai/generative_models\n-py\", line 331, in generate_content\n\nresponse = self._client.generate_content(\n\nFile \"/Users/bhuvanarora/excuse-generator/.venv/lib/python3.11/site-packages/google/ai/generat ive language_vibeta/s\nervices/generative_service/client.py\", line 835, in generate_content a\nresponse = rpc(\n\nFile \"/Users/bhuvanarora/excuse-generator/.venv/lib/python3.11/site-packages/google/api_core/gapic_v1/method. py\",\nline 131, in _call_\nreturn wrapped_func(xargs, **kwargs)\n\n'\nFile \"/Users/bhuvanarora/excuse-generator/.venv/lib/python3.11/site-packages/google/api_core/retry/retry_unary.py\" =\n, line 294, in retry_wrapped_func\nreturn retry_target(\n\nFile \"/Users/bhuvanarora/excuse-generator/.venv/lib/python3.11/site-packages/google/api_core/retry/retry_unary.py\"\n, line 156, in retry_target\nnext_sleep = _retry_error_helper(\n\nFile \"/Users/bhuvanarora/excuse-generator/.venv/lib/python3.11/site-packages/google/api_core/retry/retry_base.py\",\nline 214, in _retry_error_helper\nraise final_exc from source_exc\nFile \"/Users/bhuvanarora/excuse-generator/.venv/lib/python3.11/site-packages/google/api_core/retry/retry_unary.py\"\n, line 147, in retry_target\nresult = target()\nFile \"/Users/bhuvanarora/excuse-generator/.venv/lib/python3.11/site-packages/google/api_core/timeout.py\", line 130\n, in func_with_timeout\nreturn func(*args, +kkwargs)\n\nFile \"/Users/bhuvanarora/excuse-generator/.venv/lib/python3.11/site-packages/google/api_core/grpc_helpers.py\", lin\ne 78, in error_remapped_callable\nraise exceptions. from_grpc_error(exc) from exc\ngoogle.api_core.exceptions.NotFound: 404 models/gemini-pro is not found for API version vibeta, or is not supported\nfor generateContent. Call ListModels to see the list of available models and their supported methods.\n\nQ- Ln62,Col23 Spaces:4 UTF-8 LF {} Python & 3.13.2 64.\n\n*\n\n@ iS)\n\n\u00a9 &8 \u00a9B S 3%%) F Q S \u00a9 WedJul2 10:52AM\n@ iG\n\nMaccy\n\neee OG Intelligent Excuse Generator Plan >\n\nBhuvan\n\n\u00a9 excuse_api.py x\nMessage Bhuvan\n\n+ @ &\n\nexcuse-generator % uvicorn excuse_api:app\n--reload INFO: Will watch for\nchanges in these directories: ['/Users/bhuv...\n\n(scope, receive, send)\nFile \"/Users/bhuvanarora/excuse-generator/.venv/lib/ wo\n\n@ (.venv) bhuvanarora@Bhuvans-MacBook-Pro\n\npython3.11/site-packages/starlette/_exception_handler.py\",\nline 53, in wrapped_app\n\nraise exc\nShow full message"
}