{
  "timestamp": "2025-07-02_09-55-52",
  "active_window": "Electron",
  "focused_text": "Could not extract AXValue from focused element",
  "clipboard": "curl -X POST http://127.0.0.1:8000/generate \\\n     -H \"Content-Type: application/json\" \\\n     -d '{\"scenario\":\"missed class\",\"urgency\":\"panic\"}'",
  "vscode_text": "OPENAI_API_KEY=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",
  "ocr_text": "Code File Edit Selection View Go  Run_ Terminal Window\u2019 Help 3 32%8) FQ B Wed Jul 2 9:55AM\n+\n\n& List of research pap: X [Artificial Intelligence X | CO NLP1.ipynb-Colab X CO NLP1.ipynb-Colab X [J LAUNCHED Global X = \u2122 Launched - Artificial X _Artificial_Intelligence_C- X J Al-05-BBLEN4 x \u00a9 Openal x @ aptkeys - OpenAl Ai X\n\nO <7 Ce O @G = platform.openai.com/settings/organization/api-keys Intelligent Excuse Generator Plan > y=\nBhuvan\n\u00a9 eee@ \u20ac 2 excuse-generator By BHW\non 2 ;\ngy | oO EXPLORER J Welcome \u00ae excuse_api.py 4, U \u00a9 .env Ux >\nV EXCUSE-GENERATOR @ .env wreloaced d th dd in 2nd\nn q q \u2014\u2014 | | reloaded server and ran the same commanagd In 2n\n\u00a9 PP > \u2014Byeache_ 1 OPENAT_API_KEY=sk-proj-\u2014fbjMM3ZWBJFWqcoNxxImtmkgmE L5ner8TF5Hw8isFAx8uZ\\ .\nv veny server still\npay > lia PROBLEMS @ OUTPUT DEBUGCONSOLE TERMINAL PORTS. tv A xX\n> include OO\n. in __call__ * | BJ pyth...\nS > lib await super().__call__(scope, receive, send) x] zsh\nFo  pyvenv.cfg U File \"/Users/bhuvanarora/excuse-generator/.venv/1lib/python3.11/site-packages/starlette/applications.py\", line 112, =) ZS Thought for a few seconds >\nin __call__\nFR @ env U await self.middleware_stack(scope, receive, send) ; ; gl curl will always just say \u201cInternal Server Error\u201d unless we look at the server tab.\n\u00ae excuse_api.py 4,U File \"/Users/bhuvanarora/excuse-generator/.venv/lib/python3.11/site-packages/starlette/middleware/errors.py\", line . . . .\nA} (itempiisem u 187, in _call__ We need to read the red traceback that uvicorn prints, otherwise we're blind.\np raise exc\nA = requirements.txt U File \"/Users/bhuvanarora/excuse-generator/.venv/lib/python3.11/site-packages/starlette/middleware/errors.py\", line\n\n165, in __call__\nawait self.app(scope, receive, _send)\nFile \"/Users/bhuvanarora/excuse-generator/.venv/lib/python3.11/site-packages/starlette/middleware/exceptions.py\",\nline 62, in __call__\n\nawait wrap_app_handling_exceptions(self.app, conn)(scope, receive, send) i i 1\nFile \"/Users/bhuvanarora/excuse-generator/.venv/1lib/python3.11/site-packages/starlette/_exception_handler.py\", lin 1 Open the tab that Is running uvicorn\ne 53, in wrapped_app\nraise exc\nFile \"/Users/bhuvanarora/excuse-generator/.venv/lib/python3.11/site-packages/starlette/_exception_handler.py\", lin .\ne 42, in wrapped_app It should show a line like:\n\nawait app(scope, receive, sender)\nFile \"/Users/bhuvanarora/excuse-generator/.venv/lib/python3.11/site-packages/starlette/routing.py\", line 714, in _\ncall__ .\n\nawait self.middleware_stack(scope, receive, send) oO Copy\nFile \"/Users/bhuvanarora/excuse-generator/.venv/lib/python3.11/site-packages/starlette/routing.py\", line 734, in a\n\nawait route.handle(scope, receive, send) . + | 5\nFile \"/Users/bhuvanarora/excuse-generator/.venv/lib/python3.11/site-packages/starlette/routing.py\", line 288, in h INFO: Uvicorn reletntnlatinks) i http:\n\nandle\nawait self.app(scope, receive, send)\n\nFile \"/Users/bhuvanarora/excuse-generator/.venv/lib/python3.11/site-packages/starlette/routing.py\", line 76, in ap If you don't see that, the server isn\u2019t running\u2014start it again:\n\npp\n\np\nawait wrap_app_handling_exceptions(app, request) (scope, receive, send)\nFile \"/Users/bhuvanarora/excuse-generator/.venv/lib/python3.11/site-packages/starlette/_exception_handler.py\", lin\ne 53, in wrapped_app bash oO Copy\nraise exc\nFile \"/Users/bhuvanarora/excuse-generator/.venv/lib/python3.11/site-packages/starlette/_exception_handler.py\", lin\ne 42, in wrapped_app\nawait app(scope, receive, sender)\nFile \"/Users/bhuvanarora/excuse-generator/.venv/lib/python3.11/site-packages/starlette/routing.py\", line 73, in ap\n\nuvicorn excuse_api:app -\u2014-reload\n\nresponse = await f(request)\nFile \"/Users/bhuvanarora/excuse-generator/.venv/lib/python3.11/site-packages/fastapi/routing.py\", line 301, in app\nraw_response = await run_endpoint_function(\n\nFile \"/Users/bhuvanarora/excuse-generator/.venv/lib/python3.11/site-packages/fastapi/routing.py\", line 214, in run 2 Trigger the error while watching the server 8\n_endpoint_function\n()) return await run_in_threadpool(dependant.call, *values)\n\nFile \"/Users/bhuvanarora/excuse-generator/.venv/lib/python3.11/site-packages/starlette/concurrency.py\", line 37, i 9 rary\ns > OUTLINE n run_in_threadpool Keep that uvicorn tab visible. v\n\nreturn await anyio.to_thread. run_sync( func)\n\n> TIMELINE AAAAAAAAAAAAAARAAAAAAARAARAARAARAAARL\nLi | maint @ @Wo0A4 Q_Ln1,Col180 Spaces:4 UTF-8 LF {} Properties @& QO\nMessage Bhuvan\n\n+ @\u00ae@ ov\n\n{ | fi \u00a2\n\nSe : \u00a9)\n\n\u2014 =\n. . . .\n\n=]\n\n880068820"
}