{
  "timestamp": "2025-07-02_10-48-08",
  "active_window": "ChatGPT",
  "focused_text": "Could not extract AXValue from focused element",
  "clipboard": " File \"/Users/bhuvanarora/.pyenv/versions/3.11.13/lib/python3.11/asyncio/runners.py\", line 190, in run\n    return runner.run(main)\n           ^^^^^^^^^^^^^^^^\n  File \"/Users/bhuvanarora/.pyenv/versions/3.11.13/lib/python3.11/asyncio/runners.py\", line 118, in run\n    return self._loop.run_until_complete(task)\n           ^^^^^^^^^^^^^^^^^^^^^^^^^^^^^^^^^^^\n  File \"/Users/bhuvanarora/.pyenv/versions/3.11.13/lib/python3.11/asyncio/base_events.py\", line 654, in run_until_complete\n    return future.result()\n           ^^^^^^^^^^^^^^^\n  File \"/Users/bhuvanarora/excuse-generator/.venv/lib/python3.11/site-packages/uvicorn/server.py\", line 71, in serve\n    await self._serve(sockets)\n  File \"/Users/bhuvanarora/excuse-generator/.venv/lib/python3.11/site-packages/uvicorn/server.py\", line 78, in _serve\n    config.load()\n  File \"/Users/bhuvanarora/excuse-generator/.venv/lib/python3.11/site-packages/uvicorn/config.py\", line 436, in load\n    self.loaded_app = import_from_string(self.app)\n                      ^^^^^^^^^^^^^^^^^^^^^^^^^^^^\n  File \"/Users/bhuvanarora/excuse-generator/.venv/lib/python3.11/site-packages/uvicorn/importer.py\", line 19, in import_from_string\n    module = importlib.import_module(module_str)\n             ^^^^^^^^^^^^^^^^^^^^^^^^^^^^^^^^^^^\n  File \"/Users/bhuvanarora/.pyenv/versions/3.11.13/lib/python3.11/importlib/__init__.py\", line 126, in import_module\n    return _bootstrap._gcd_import(name[level:], package, level)\n           ^^^^^^^^^^^^^^^^^^^^^^^^^^^^^^^^^^^^^^^^^^^^^^^^^^^^\n  File \"<frozen importlib._bootstrap>\", line 1204, in _gcd_import\n  File \"<frozen importlib._bootstrap>\", line 1176, in _find_and_load\n  File \"<frozen importlib._bootstrap>\", line 1147, in _find_and_load_unlocked\n  File \"<frozen importlib._bootstrap>\", line 690, in _load_unlocked\n  File \"<frozen importlib._bootstrap_external>\", line 940, in exec_module\n  File \"<frozen importlib._bootstrap>\", line 241, in _call_with_frames_removed\n  File \"/Users/bhuvanarora/excuse-generator/excuse_api.py\", line 15, in <module>\n    print(\">>> model being used:\", model._name)\n                                  ^^^^^^^^^^^\nAttributeError: 'GenerativeModel' object has no attribute '_name'",
  "vscode_text": "# excuse_api.py\nimport os, json, time, hashlib\nfrom pathlib import Path\nfrom dotenv import load_dotenv, find_dotenv\nload_dotenv(find_dotenv(), override=True)\n\n\n\nfrom fastapi import FastAPI\nfrom pydantic import BaseModel\n\nimport google.generativeai as genai\ngenai.configure(api_key=os.getenv(\"GEMINI_KEY\"))\nmodel = genai.GenerativeModel(\"gemini-pro\")\nprint(\">>> model being used:\", model._name) \n# ---------- simple \u201cDB\u201d ----------\nDATA = Path(\"history.json\")\nif not DATA.exists():\n    DATA.write_text(\"[]\")          # seed empty list\n\n\n\n# ---------- FastAPI app ----------\napp = FastAPI()\n\nclass Req(BaseModel):\n    scenario: str  # e.g. \"missed class\"\n    urgency: str   # \"low\" | \"medium\" | \"panic\"\n\nSYSTEM_PROMPT = \"\"\"\nYou are an elite alibi-creator.\nReturn a JSON with:\n  excuse               (\u2264 50 words),\n  believability_score  (0-1),\n  chat_log             (short WhatsApp-style proof)\n\"\"\"\n\n# ---------- /generate ----------\n@app.post(\"/generate\")\ndef generate(r: Req):\n    prompt = f\"Scenario: {r.scenario}\\nUrgency: {r.urgency}\"\n    full_prompt = f\"{SYSTEM_PROMPT}\\nScenario: {r.scenario}\\nUrgency: {r.urgency}\"\n    out = json.loads(model.generate_content(full_prompt).text)\n    entry = {\n        \"id\": hashlib.md5(out[\"excuse\"].encode()).hexdigest(),\n        \"ts\": time.time(),\n        **out,\n    }\n\n    history = json.loads(DATA.read_text())\n    if entry[\"id\"] not in {h[\"id\"] for h in history}:   # de-dupe\n        history.append(entry)\n        DATA.write_text(json.dumps(history, indent=2))\n\n    return entry\n\n# ---------- /top?n=5 ----------\n@app.get(\"/top\")\ndef top(n: int = 5):\n    history = json.loads(DATA.read_text())\n    history.sort(key=lambda x: x[\"believability_score\"], reverse=True)\n    return history[:n]",
  "ocr_text": "Ow \u00ae 0\n\nChatGPT File Edit View Window\u2019 Help\n\n=} List of research * Artificial Intellige CO NLP_1.ipynb - Co CO NLP_1.ipynb - Cc [a LAUNCHED Glok\n\n- > CO O 6 = aistudio.google.com/apikey\n\nGoogle Al Studio\n\nP excuse-generator\n\nEXPLORER x Welcome @ excuse_api.py 4,U X % .env U\n\nVv EXCUSE-GENERATOR @ excuse_api.py > ...\n\n> __pycache__ 7\n\no a O\nVV venv 8\n\nih Usi J)\n> bin\n9 from fastapi import FastAPI\n\nCh oe > include\n\n> lib\n>\n& \u00a9 pyvenv.cfg\n\n00\n\nPROBLEMS @ OUTPUT DEBUG CONSOLE TERMINAL PORTS.\n\n\u00a9 .env\n\nU\n\nU Process SpawnProcess-1:\nES @ excuse_api.py 4,U\n\nU\n\nU\n\nTraceback (most recent call last):\n\n{} history.json ap\n\nA = requirements.txt self.run()\n\nM Launched - Artif\n\nArtificial_Intelligence\n\n O\nwe il\n\n-} pyth\u00a2\n>-| zsh\n\nFile \"/Users/bhuvanarora/.pyenv/versions/3.11.13/lib/python3.11/multiprocessing/process.py\", line 314, in _bootstr\n\nFile \"/Users/bhuvanarora/.pyenv/versions/3.11.13/lib/python3.11/multiprocessing/process.py\", line 108, in run\n\nself._target(*self._args, *kself._kwargs)\n\nFile \"/Users/bhuvanarora/excuse-generator/.venv/lib/python3.11/site-packages/uvicorn/_subprocess.py\", line 80, in\n\nsubprocess_started\ntarget (sockets=sockets)\n\nFile \"/Users/bhuvanarora/excuse-generator/.venv/lib/python3.11/site-packages/uvicorn/server.py\", line\n\nreturn asyncio.run(self.serve(sockets=sockets) )\n\nFile \"/Users/bhuvanarora/.pyenv/versions/3.11.13/lib/python3.11/asyncio/runners.py\", line 190, in run\n\nreturn runner. run(main)\n\nFile \"/Users/bhuvanarora/.pyenv/versions/3.11.13/1lib/python3.11/asyncio/runners.py\", line 118, in run\n\nreturn self._loop. run_until_complete(task)\n\nFile \"/Users/bhuvanarora/.pyenv/versions/3.11.13/lib/python3.11/asyncio/base_events.py\", line 654, in\n\nmplete\nreturn future. result()\n\nFile \"/Users/bhuvanarora/excuse-generator/.venv/lib/python3.11/site-packages/uvicorn/server.py\", line\n\nawait self._serve(sockets)\n\nFile \"/Users/bhuvanarora/excuse-generator/.venv/lib/python3.11/site-packages/uvicorn/server.py\", line\n\ne\nconfig. load()\n\nFile \"/Users/bhuvanarora/excuse-generator/.venv/lib/python3.11/site-packages/uvicorn/config.py\", line\n\nself. loaded_app = import_from_string(self.app)\n\n67, in run\n\nrun_until_co\n\n71, in serve\n\n78, in _serv\n\n436, in load\n\nFile \"/Users/bhuvanarora/excuse-generator/.venv/lib/python3.11/site-packages/uvicorn/importer.py\", line 19, in imp\n\nort_from_string\nmodule = importlib. import_module(module_str)\n\nFile \"/Users/bhuvanarora/.pyenv/versions/3.11.13/lib/python3.11/importlib/__init__.py\", line 126, in import_module\n\nreturn _bootstrap._gcd_import(name[level:], package, level)\n\nFile \"<frozen importlib._bootstrap>\", line 1204, in _gcd_import\nFile \"<frozen importlib._bootstrap>\", line 1176, in _find_and_load\nFile \"<frozen importlib._bootstrap>\", line 1147, in _find_and_load_unlocked\nFile \"<frozen importlib._bootstrap>\", line 69@, in _load_unlocked\nFile \"<frozen importlib._bootstrap_external>\", line 940, in exec_module\n\n@ File \"<frozen importlib._bootstrap>\", line 241, in _call_with_frames_removed\nFile \"/Users/bhuvanarora/excuse-generator/excuse_api.py\", line 15, in <module>\n\nprint(\">>> model being used:\", model._name)\nsos > OUTLINE\n> TIMELINE\n\n* in* @ 0 4\nView stat All men es ees\n\nAttributeError: 'GenerativeModel' object has no attribute '_name'\n\nSS = |\no\n\nQ  n14,Col32 Spaces:4 UTF-8 LF {} Python\n\n8 3.13.2 64\n\n240%) FQ ES\n\n6&8 OO 8\n\n9% Get API key | G X\n\nIntelligent Excuse Generator Plan >\nBhuvan\n\neco MO @G\n\nFile \"/Users/bhuvanarora/excuse-generator/\nexcuse_api.py\", line 15, in <module>\n\nprint(\">>> model being used:\", model._name)\n\nAAAARARADRAAN\n\nAttributeError: 'GenerativeModel' object has no attribute\n\"_name'\n\nThought for a couple of seconds\nFound it\u2014the server is crashing before it even starts because the debug line tries to access a\nprivate attribute that doesn't exist in the current SDK:\n\npython \u00a9) Copy\n\nprint(\">>> model being used:\", model._name)\n\nFix (5 seconds)\n\n1. Delete or comment out that line.\n\npython \u00a9) Copy\n\n2. Restart Uvicorn cleanly:\n\nbash O) Copy\n\nCtr1-C\nuvicorn excuse_api:app --reload\n\n\u00a9 excuse_api.py x\nMessage Bhuvan\n\n+ @ &\n\n=]\n\n@ Wed Jul 2 10:48AM"
}