{
  "timestamp": "2025-07-02_10-03-08",
  "active_window": "ChatGPT",
  "focused_text": "Could not extract AXValue from focused element",
  "clipboard": "echo $OPENAI_API_KEY           # \u2190 should print nothing",
  "vscode_text": "OPENAI_API_KEY=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",
  "ocr_text": "6\n\no\nS\n\n\u00a9\n\nChatGPT File Edit View Window\u2019 Help 6 \u20ac8 \u00a9GD O S 32%f) FF Q BS \u00a9 WedJul2 10:03AM\n= List of research pape X Artificial Intelligence X CO NLP_1.ipynb - Colab X CO NLP_1.ipynb - Colab X ca LAUNCHED Global X \u2122@ Launched - Artificial X Artificial_Intelligence_Ce X (B\u00ae al-05-BBLEN4 x \u00a9 Opendl x So API keys - OpenAl A! X\n\n, mp _\n32 platform.openai.com/settings/organization/api-keys Intelligent Excuse Generator Plan > y =\n\n&\u20ac> GA OB =p p /settings/org [api-key eco MD G_Miellig a\n\n<> P excuse-generator By BOW\n| oO EXPLORER J Welcome \u00ae excuse_api.py 4, U \u00a9 .env Ux >\nV EXCUSE-GENERATOR  .env\n\nP > __pycache__\n\nv venv\npa > bin\n> include\n> lib\nae\n\n\u00a9 pyvenv.cfg\n& .env\n\nHS @ excuse_api.py\n\n{} history.json\nA = requirements.txt\n\n@\n$03 > OUTLINE\n\n> TIMELINE\n\nWE & maine @0A4\n\nU\nU\nU\nU\nU\n\n1 OPENAT_API_KEY=sk-proj-\u2014fbjMM3ZWBJFWqcoNxxImtmkgmE L5ner8TF5Hw8isFAx8uZ\\ Thought for 25 seconds >\n\nPROBLEMS @ OUTPUT DEBUG CONSOLE TERMINAL PORTS toy oo AM The traceback tells us the server is still sending \"your_api_key\" to OpenAl, so the real key\n\nAAA AAA * | zsh in . env is not being loaded.\nFile \"/Users/bhuvanarora/excuse-generator/.venv/lib/python3.11/site-packages/fastapi/routing.py\", line 301, in app\nraw_response = await run_endpoint_function( Let's replace that placeholder once and verify what the code is actually seeing.\nFile \"/Users/bhuvanarora/excuse-generator/.venv/lib/python3.11/site-packages/fastapi/routing.py\", line 214, in run\n_endpoint_function\nreturn await run_in_threadpool(dependant.call, *values)\n\nFile \"/Users/bhuvanarora/excuse-generator/.venv/lib/python3.11/site-packages/starlette/concurrency.py\", line 37, i\n\ni h id 1 4 4\nn Fupaturn await enyio.to_thread. run_syne(func) 1 Check what the app sees inside Python\n\nFile \"/Users/bhuvanarora/excuse-generator/.venv/lib/python3.11/site-packages/anyio/to_thread.py\", line 56, in run_\nsync\nreturn await get_async_backend().run_sync_in_worker_thread(\nFile \"/Users/bhuvanarora/excuse-generator/.venv/lib/python3.11/site-packages/anyio/_backends/_asyncio.py\", line 24\n70, in run_sync_in_worker_thread\n\nIn the VS Code terminal (still inside .venv) run this one-liner:\n\nreturn await future bash oO Copy\nFile \"/Users/bhuvanarora/excuse-generator/.venv/lib/python3.11/site-packages/anyio/_backends/_asyncio.py\", line 96,\n7, in run _ ' 1\nresult = context.run(func, *args) python <<'PY ;\nAARAAAARARARARAAAARARARAA import os ' pathlib ' dot env\n\nFile \"/Users/bhuvanarora/excuse-generator/excuse_api.py\", line 37, in generate dotenv.load dotenv(override=True)\nres = client.chat.completions.create( i a\n\nAAAAAAAAAAAAAAAAAAAAAAAAAAAAAAA print(\"PYTHON SEES:\", os.getenv(\"OPENAI_API_KEY\") )\nFile \"/Users/bhuvanarora/excuse-generator/.venv/1lib/python3.11/site-packages/openai/_utils/_utils.py\", line 287, i PY\nn wrapper\nreturn func(*args, +kkwargs)\nFile \"/Users/bhuvanarora/excuse-generator/.venv/lib/python3.11/site-packages/openai/resources/chat/completions/com\npletions.py\", line 1087, in create\nreturn self._post(\n\n+ If it prints your long sk\u2014proj-... key > good, jump to step 3.\n\nFile \"/Users/bhuvanarora/excuse-generator/.venv/lib/python3.11/site-packages/openai/_base_client.py\", line 1249, i If it prints None or your_api_key > the key isn't being found; fix it with step 2.\n\nn post 1\n\nreturn cast(ResponseT, self.request(cast_to, opts, stream=stream, stream_cls=stream_cls) )\n\nFile \"/Users/bhuvanarora/excuse-generator/.venv/lib/python3.11/site-packages/openai/_base_client.py\", line 1037, i\n\nn request\n\nraise self._make_status_error_from_response(err.response) from None\nopenai.AuthenticationError: Error code: 401 - {'error': {'message': \u2018Incorrect API key provided: your_api_key. You c\nan find your API key at https://platform.openai.com/account/api-keys.', \u2018type': \u2018invalid_request_error', \u2018param': No\nne, \u2018code': 'invalid_api_key'}}\n\n2 Make absolutely sure only the real key exists\n\necho $OPENAI_API_KEY # \u00a9 should print nothing*CINFO: Shutting down 1. Delete/rename any placeholder file that might still be loaded:\n\nINFO: Waiting for application shutdown.\n\nINFO: Application shutdown complete. v\n\nINFO: Finished server process [90338] bash DS) Cany\nINFO: Stopping reloader process [90336] ~\n\n@ (.venv) bhuvanarora@Bhuvans\u2014-MacBook-Pro excuse-generator % echo $OPENAI_API_KEY\n\nyour_api_key .\n(.venv) bhuvanarora@Bhuvans-MacBook-Pro excuse-generator % [] ' ( Work with Code Tab x\nQ _Ln1,Col180 Spaces:4 UTF-8 LF {} Properties 8 (|\n\nMessage Bhuvan\n\n+ @\u00ae ov\n\n{ } f \u00a2\n\n\u00a9 & : )\n\n\u2014 =\n. . . .\n\n880068820\n\n=]"
}